Workbook
Name Slicer_Statement_Type: #N/A
Name Slicer_Year: #N/A

Sheet COCA COLA CO
A1: Data provided by SimFin
A3: Profit & Loss statement
B4: in million USD | C4: FY '09 | D4: FY '10 | E4: FY '11 | F4: FY '12 | G4: FY '13 | H4: FY '14 | I4: FY '15 | J4: FY '16 | K4: FY '17 | L4: FY '18
B5: NET OPERATING REVENUES | C5: 30990 | D5: 35119 | E5: 46542 | F5: 48017 | G5: 46854 | H5: 45998 | I5: 44294 | J5: 41863 | K5: 35410 | L5: 31856
B6: Cost of goods sold | C6: 11088 | D6: 12693 | E6: 18215 | F6: 19053 | G6: 18421 | H6: 17889 | I6: 17482 | J6: 16465 | K6: 13255 | L6: 11770
B7: Gross Profit | C7: 19902 | D7: 22426 | E7: 28327 | F7: 28964 | G7: 28433 | H7: 28109 | I7: 26812 | J7: 25398 | K7: 22155 | L7: 20086
B8: Selling, general and administrative expenses | C8: 11358 | D8: 13194 | E8: 17422 | F8: 17738 | G8: 17310 | H8: 17218 | I8: 16427 | J8: 15262 | K8: 12654 | L8: 10307
B9: Other operating charges | C9: 313 | D9: 819 | E9: 732 | F9: 447 | G9: 895 | H9: 1183 | I9: 1657 | J9: 1510 | K9: 1902 | L9: 1079
B10: Operating Income | C10: 8231 | D10: 8413 | E10: 10173 | F10: 10779 | G10: 10228 | H10: 9708 | I10: 8728 | J10: 8626 | K10: 7599 | L10: 8700
B11: Interest income | C11: 249 | D11: 317 | E11: 483 | F11: 471 | G11: 534 | H11: 594 | I11: 613 | J11: 642 | K11: 677 | L11: 682
B12: Interest expense | C12: 355 | D12: 733 | E12: 417 | F12: 397 | G12: 463 | H12: 483 | I12: 856 | J12: 733 | K12: 841 | L12: 919
B13: Equity income (loss) - net | C13: 781 | D13: 1025 | E13: 690 | F13: 819 | G13: 602 | H13: 769 | I13: 489 | J13: 835 | K13: 1071 | L13: 1008
B14: Other income (loss) - net | C14: 40 | D14: 5185 | E14: 529 | F14: 137 | G14: 576 | H14: -1263 | I14: 631 | J14: -1234 | K14: -1764 | L14: -1121
B15: Income before income taxes | C15: 8946 | D15: 14207 | E15: 11458 | F15: 11809 | G15: 11477 | H15: 9325 | I15: 9605 | J15: 8136 | K15: 6742 | L15: 8350
B16: Income taxes | C16: 2040 | D16: 2370 | E16: 2812 | F16: 2723 | G16: 2851 | H16: 2201 | I16: 2239 | J16: 1586 | K16: 5560 | L16: 1623
... B18: Less: Net income attributable to noncontrolling interests | C18: 82 | D18: 50 | E18: 62 | F18: 67 | G18: 42 | H18: 26 | I18: 15 | J18: 23 | K18: 35 | L18: 42
B19: Net income from continuing operations | I19: 7366 | J19: 6550 | K19: 1182 | L19: 6727
B20: Income (Loss) from Discontinued Operations, Net of Tax, Including Portion Attributable to Noncontrolling Interest | I20: 0 | J20: 0 | K20: 101 | L20: -251
B21: NET INCOME ATTRIBUTABLE TO SHAREOWNERS OF THE COCA-COLA COMPANY | C21: 6824 | D21: 11787 | E21: 8584 | F21: 9019 | G21: 8584 | H21: 7098 | I21: 7351 | J21: 6527 | K21: 1248 | L21: 6434
A23: Balance Sheet
B24: in million USD | C24: FY '09 | D24: FY '10 | E24: FY '11 | F24: FY '12 | G24: FY '13 | H24: FY '14 | I24: FY '15 | J24: FY '16 | K24: FY '17 | L24: FY '18
B25: Assets
B26: Cash and cash equivalents | C26: 7021 | D26: 8517 | E26: 12803 | F26: 8442 | G26: 10414 | H26: 8958 | I26: 7309 | J26: 8555 | K26: 6006 | L26: 8926
B27: Short-term investments | C27: 2130 | D27: 2682 | E27: 1088 | F27: 5017 | G27: 6707 | H27: 9052 | I27: 8322 | J27: 9595 | K27: 9352 | L27: 2025
B28: Total cash, cash equivalents and short-term investments | C28: 9151 | D28: 11199 | E28: 13891 | F28: 13459 | G28: 17121 | H28: 18010 | I28: 15631 | J28: 18150 | K28: 15358 | L28: 10951
B29: Marketable securities | C29: 62 | D29: 138 | E29: 144 | F29: 3092 | G29: 3147 | H29: 3665 | I29: 4269 | J29: 4051 | K29: 5317 | L29: 5013
B30: Trade accounts receivable, less allowances | C30: 3758 | D30: 4430 | E30: 4920 | F30: 4759 | G30: 4873 | H30: 4466 | I30: 3941 | J30: 3856 | K30: 3667 | L30: 3396
B31: Inventories | C31: 2354 | D31: 2650 | E31: 3092 | F31: 3264 | G31: 3277 | H31: 3100 | I31: 2902 | J31: 2675 | K31: 2655 | L31: 2766
B32: Prepaid expenses and other assets | C32: 2226 | D32: 3162 | E32: 3450 | F32: 2781 | G32: 2886 | H32: 3066 | I32: 2752 | J32: 2481 | K32: 2000 | L32: 1962
B33: Assets held for sale | E33: 0 | F33: 2973 | G33: 0 | H33: 679 | I33: 3900 | J33: 0 | K33: 7329 | L33: 6546
B34: Assets held for sale | J34: 2797 | K34: 219 | L34: 0
B35: Total current assets | C35: 17551 | D35: 21579 | E35: 25497 | F35: 30328 | G35: 31304 | H35: 32986 | I35: 33395 | J35: 34010 | K35: 36545 | L35: 30634
B36: Equity method investments | C36: 6217 | D36: 6954 | E36: 7233 | F36: 9216 | G36: 10393 | H36: 9947 | I36: 12318 | J36: 16260 | K36: 20856 | L36: 19407
B37: Other investments | C37: 538 | D37: 631 | E37: 1141 | F37: 1232 | G37: 1119 | H37: 3678 | I37: 3470 | J37: 989 | K37: 1096 | L37: 867
B38: Other assets | C38: 1976 | D38: 2121 | E38: 3495 | F38: 3585 | G38: 4661 | H38: 4407 | I38: 4110 | J38: 4248 | K38: 4230 | L38: 4139
B39: Property, plant and equipment - net | C39: 9561 | D39: 14727 | E39: 14939 | F39: 14476 | G39: 14967 | H39: 14633 | I39: 12571 | J39: 10635 | K39: 8203 | L39: 8232
B40: Deferred income tax assets | K40: 330 | L40: 2667
B41: TRADEMARKS WITH INDEFINITE LIVES | C41: 6183 | D41: 6356 | E41: 6430 | F41: 6527 | G41: 6744 | H41: 6533 | I41: 5989 | J41: 6097 | K41: 6729 | L41: 6682
B42: BOTTLERS' FRANCHISE RIGHTS WITH INDEFINITE LIVES | C42: 1953 | D42: 7511 | E42: 7770 | F42: 7405 | G42: 7415 | H42: 6689 | I42: 6000 | J42: 3676 | K42: 138 | L42: 51
B43: Goodwill | C43: 4224 | D43: 11665 | E43: 12219 | F43: 12255 | G43: 12312 | H43: 12100 | I43: 11289 | J43: 10629 | K43: 9401 | L43: 10263
...

Sheet Pivot Table 1(Viewing Only)
A3: Row Labels | B3: Sum of Amount
A4: 2009 | B4: 399741
A5: Balance Sheet | B5: 285252
A6: Accounts payable and accrued expenses | B6: 6657
A7: Accrued income taxes | B7: 264
A8: Accumulated other comprehensive income (loss) | B8: -757
A9: Assets held for sale | B9: 0
A10: BOTTLERS' FRANCHISE RIGHTS WITH INDEFINITE LIVES | B10: 1953
A11: Capital surplus | B11: 8537
A12: Cash and cash equivalents | B12: 7021
A13: Common stock | B13: 880
A14: Current maturities of long-term debt | B14: 51
A15: Deferred income tax assets | B15: 0
A16: Deferred income taxes | B16: 1580
... A99: Selling, general and administrative expenses | B99: 11358
A100: 2010 | B100: 550119
A101: Balance Sheet | B101: 405290
A102: Accounts payable and accrued expenses | B102: 8859
A103: Accrued income taxes | B103: 273
A104: Accumulated other comprehensive income (loss) | B104: -1450
A105: Assets held for sale | B105: 0
A106: BOTTLERS' FRANCHISE RIGHTS WITH INDEFINITE LIVES | B106: 7511
A107: Capital surplus | B107: 10057
A108: Cash and cash equivalents | B108: 8517
A109: Common stock | B109: 880
A110: Current maturities of long-term debt | B110: 1276
A111: Deferred income tax assets | B111: 0
A112: Deferred income taxes | B112: 4261
... A195: Selling, general and administrative expenses | B195: 13194
A196: 2011 | B196: 615503
A197: Balance Sheet | B197: 447123
A198: Accounts payable and accrued expenses | B198: 9009
A199: Accrued income taxes | B199: 362
A200: Accumulated other comprehensive income (loss) | B200: -2774
A201: Assets held for sale | B201: 0
A202: BOTTLERS' FRANCHISE RIGHTS WITH INDEFINITE LIVES | B202: 7770
A203: Capital surplus | B203: 10332
A204: Cash and cash equivalents | B204: 12803
A205: Common stock | B205: 1760
A206: Current maturities of long-term debt | B206: 2041
...

Sheet Table Format
A1: Statement_type | B1: Metric | C1: Year | D1: Amount | H1: Xlookup
A2: Profit & Loss Statement | B2: NET OPERATING REVENUES | C2: 2009 | D2: ='COCA COLA CO'!C5 -> 30990 | H2: Profit & Loss Statement | I2: NET INCOME ATTRIBUTABLE TO SHAREOWNERS OF THE COCA-COLA COMPANY
A3: Profit & Loss Statement | B3: Cost of goods sold | C3: 2009 | D3: ='COCA COLA CO'!C6 -> 11088 | H3: Balance Sheet | I3: Total Assets
A4: Profit & Loss Statement | B4: Gross Profit | C4: 2009 | D4: ='COCA COLA CO'!C7 -> 19902 | H4: Cash Flow Statement | I4: Net increase (decrease) during the year
A5: Profit & Loss Statement | B5: Selling, general and administrative expenses | C5: 2009 | D5: ='COCA COLA CO'!C8 -> 11358
A6: Profit & Loss Statement | B6: Other operating charges | C6: 2009 | D6: ='COCA COLA CO'!C9 -> 313
A7: Profit & Loss Statement | B7: Operating Income | C7: 2009 | D7: ='COCA COLA CO'!C10 -> 8231
A8: Profit & Loss Statement | B8: Interest income | C8: 2009 | D8: ='COCA COLA CO'!C11 -> 249
A9: Profit & Loss Statement | B9: Interest expense | C9: 2009 | D9: ='COCA COLA CO'!C12 -> 355
A10: Profit & Loss Statement | B10: Equity income (loss) - net | C10: 2009 | D10: ='COCA COLA CO'!C13 -> 781
A11: Profit & Loss Statement | B11: Other income (loss) - net | C11: 2009 | D11: ='COCA COLA CO'!C14 -> 40
A12: Profit & Loss Statement | B12: Income before income taxes | C12: 2009 | D12: ='COCA COLA CO'!C15 -> 8946
A13: Profit & Loss Statement | B13: Income taxes | C13: 2009 | D13: ='COCA COLA CO'!C16 -> 2040
A14: Profit & Loss Statement | B14: CONSOLIDATED NET INCOME | C14: 2009 | D14: ='COCA COLA CO'!C17 -> 6906
A15: Profit & Loss Statement | B15: Less: Net income attributable to noncontrolling interests | C15: 2009 | D15: ='COCA COLA CO'!C18 -> 82
A16: Profit & Loss Statement | B16: Net income from continuing operations | C16: 2009 | D16: ='COCA COLA CO'!C19 -> 0
... A18: Profit & Loss Statement | B18: NET INCOME ATTRIBUTABLE TO SHAREOWNERS OF THE COCA-COLA COMPANY | C18: 2009 | D18: ='COCA COLA CO'!C21 -> 6824
A19: Profit & Loss Statement | B19: NET OPERATING REVENUES | C19: 2010 | D19: ='COCA COLA CO'!D5 -> 35119
A20: Profit & Loss Statement | B20: Cost of goods sold | C20: 2010 | D20: ='COCA COLA CO'!D6 -> 12693
A21: Profit & Loss Statement | B21: Gross Profit | C21: 2010 | D21: ='COCA COLA CO'!D7 -> 22426
A22: Profit & Loss Statement | B22: Selling, general and administrative expenses | C22: 2010 | D22: ='COCA COLA CO'!D8 -> 13194
A23: Profit & Loss Statement | B23: Other operating charges | C23: 2010 | D23: ='COCA COLA CO'!D9 -> 819
A24: Profit & Loss Statement | B24: Operating Income | C24: 2010 | D24: ='COCA COLA CO'!D10 -> 8413
A25: Profit & Loss Statement | B25: Interest income | C25: 2010 | D25: ='COCA COLA CO'!D11 -> 317
A26: Profit & Loss Statement | B26: Interest expense | C26: 2010 | D26: ='COCA COLA CO'!D12 -> 733
A27: Profit & Loss Statement | B27: Equity income (loss) - net | C27: 2010 | D27: ='COCA COLA CO'!D13 -> 1025
A28: Profit & Loss Statement | B28: Other income (loss) - net | C28: 2010 | D28: ='COCA COLA CO'!D14 -> 5185
A29: Profit & Loss Statement | B29: Income before income taxes | C29: 2010 | D29: ='COCA COLA CO'!D15 -> 14207
A30: Profit & Loss Statement | B30: Income taxes | C30: 2010 | D30: ='COCA COLA CO'!D16 -> 2370
... A35: Profit & Loss Statement | B35: NET INCOME ATTRIBUTABLE TO SHAREOWNERS OF THE COCA-COLA COMPANY | C35: 2010 | D35: ='COCA COLA CO'!D21 -> 11787
A36: Profit & Loss Statement | B36: NET OPERATING REVENUES | C36: 2011 | D36: ='COCA COLA CO'!E5 -> 46542
A37: Profit & Loss Statement | B37: Cost of goods sold | C37: 2011 | D37: ='COCA COLA CO'!E6 -> 18215
A38: Profit & Loss Statement | B38: Gross Profit | C38: 2011 | D38: ='COCA COLA CO'!E7 -> 28327
A39: Profit & Loss Statement | B39: Selling, general and administrative expenses | C39: 2011 | D39: ='COCA COLA CO'!E8 -> 17422
A40: Profit & Loss Statement | B40: Other operating charges | C40: 2011 | D40: ='COCA COLA CO'!E9 -> 732
A41: Profit & Loss Statement | B41: Operating Income | C41: 2011 | D41: ='COCA COLA CO'!E10 -> 10173
A42: Profit & Loss Statement | B42: Interest income | C42: 2011 | D42: ='COCA COLA CO'!E11 -> 483
A43: Profit & Loss Statement | B43: Interest expense | C43: 2011 | D43: ='COCA COLA CO'!E12 -> 417
A44: Profit & Loss Statement | B44: Equity income (loss) - net | C44: 2011 | D44: ='COCA COLA CO'!E13 -> 690
A45: Profit & Loss Statement | B45: Other income (loss) - net | C45: 2011 | D45: ='COCA COLA CO'!E14 -> 529
...

Sheet Overall_Data
A3: Row Labels | B3: Sum of Price_Amount
A4: 2009 | B4: 57815
A5: Balance Sheet | B5: 48671
A6: Cash Flow Statement | B6: 2320
A7: Profit & Loss Statement | B7: 6824
A8: 2010 | B8: 86204
A9: Balance Sheet | B9: 72921
A10: Cash Flow Statement | B10: 1496
A11: Profit & Loss Statement | B11: 11787
A12: 2011 | B12: 92844
A13: Balance Sheet | B13: 79974
A14: Cash Flow Statement | B14: 4286
A15: Profit & Loss Statement | B15: 8584
A16: 2012 | B16: 90832
A17: Balance Sheet | B17: 86174
A18: Cash Flow Statement | B18: -4361
A19: Profit & Loss Statement | B19: 9019
A20: 2013 | B20: 100611
A21: Balance Sheet | B21: 90055
A22: Cash Flow Statement | B22: 1972
A23: Profit & Loss Statement | B23: 8584
A24: 2014 | B24: 97665
A25: Balance Sheet | B25: 92023
A26: Cash Flow Statement | B26: -1456
A27: Profit & Loss Statement | B27: 7098
A28: 2015 | B28: 95698
A29: Balance Sheet | B29: 89996
A30: Cash Flow Statement | B30: -1649
A31: Profit & Loss Statement | B31: 7351
A32: 2016 | B32: 95043
A33: Balance Sheet | B33: 87270
A34: Cash Flow Statement | B34: 1246
A35: Profit & Loss Statement | B35: 6527
A36: 2017 | B36: 86667
A37: Balance Sheet | B37: 87896
A38: Cash Flow Statement | B38: -2477
A39: Profit & Loss Statement | B39: 1248
A40: 2018 | B40: 92595
A41: Balance Sheet | B41: 83216
A42: Cash Flow Statement | B42: 2945
...

Sheet Negative_Cash_Flow
A3: Row Labels | B3: Sum of Price_Amount
A4: 2012 | B4: -4361
A5: Cash Flow Statement | B5: -4361
A6: 2014 | B6: -1456
A7: Cash Flow Statement | B7: -1456
A8: 2015 | B8: -1649
A9: Cash Flow Statement | B9: -1649
A10: 2017 | B10: -2477
A11: Cash Flow Statement | B11: -2477
A12: Grand Total | B12: -9943

Sheet Main_Table
A1: Statement_Type | B1: Metric | C1: Year | D1: Price_Amount
A2: Profit & Loss Statement | B2: NET INCOME ATTRIBUTABLE TO SHAREOWNERS OF THE COCA-COLA COMPANY | C2: 2009 | D2: {=_xlfn.XLOOKUP(B2 &C2,Table3[Metric] &Table3[Year],Table3[Amount],,0)} -> 6824
A3: Profit & Loss Statement | B3: NET INCOME ATTRIBUTABLE TO SHAREOWNERS OF THE COCA-COLA COMPANY | C3: 2010 | D3: {=_xlfn.XLOOKUP(B3 &C3,Table3[Metric] &Table3[Year],Table3[Amount],,0)} -> 11787
A4: Profit & Loss Statement | B4: NET INCOME ATTRIBUTABLE TO SHAREOWNERS OF THE COCA-COLA COMPANY | C4: 2011 | D4: {=_xlfn.XLOOKUP(B4 &C4,Table3[Metric] &Table3[Year],Table3[Amount],,0)} -> 8584
A5: Profit & Loss Statement | B5: NET INCOME ATTRIBUTABLE TO SHAREOWNERS OF THE COCA-COLA COMPANY | C5: 2012 | D5: {=_xlfn.XLOOKUP(B5 &C5,Table3[Metric] &Table3[Year],Table3[Amount],,0)} -> 9019
A6: Profit & Loss Statement | B6: NET INCOME ATTRIBUTABLE TO SHAREOWNERS OF THE COCA-COLA COMPANY | C6: 2013 | D6: {=_xlfn.XLOOKUP(B6 &C6,Table3[Metric] &Table3[Year],Table3[Amount],,0)} -> 8584
A7: Profit & Loss Statement | B7: NET INCOME ATTRIBUTABLE TO SHAREOWNERS OF THE COCA-COLA COMPANY | C7: 2014 | D7: {=_xlfn.XLOOKUP(B7 &C7,Table3[Metric] &Table3[Year],Table3[Amount],,0)} -> 7098
A8: Profit & Loss Statement | B8: NET INCOME ATTRIBUTABLE TO SHAREOWNERS OF THE COCA-COLA COMPANY | C8: 2015 | D8: {=_xlfn.XLOOKUP(B8 &C8,Table3[Metric] &Table3[Year],Table3[Amount],,0)} -> 7351
A9: Profit & Loss Statement | B9: NET INCOME ATTRIBUTABLE TO SHAREOWNERS OF THE COCA-COLA COMPANY | C9: 2016 | D9: {=_xlfn.XLOOKUP(B9 &C9,Table3[Metric] &Table3[Year],Table3[Amount],,0)} -> 6527
A10: Profit & Loss Statement | B10: NET INCOME ATTRIBUTABLE TO SHAREOWNERS OF THE COCA-COLA COMPANY | C10: 2017 | D10: {=_xlfn.XLOOKUP(B10 &C10,Table3[Metric] &Table3[Year],Table3[Amount],,0)} -> 1248
A11: Profit & Loss Statement | B11: NET INCOME ATTRIBUTABLE TO SHAREOWNERS OF THE COCA-COLA COMPANY | C11: 2018 | D11: {=_xlfn.XLOOKUP(B11 &C11,Table3[Metric] &Table3[Year],Table3[Amount],,0)} -> 6434
A12: Balance Sheet | B12: Total Assets | C12: 2009 | D12: {=_xlfn.XLOOKUP(B12 &C12,Table3[Metric] &Table3[Year],Table3[Amount],,0)} -> 48671
A13: Balance Sheet | B13: Total Assets | C13: 2010 | D13: {=_xlfn.XLOOKUP(B13 &C13,Table3[Metric] &Table3[Year],Table3[Amount],,0)} -> 72921
... A31: Cash Flow Statement | B31: Net increase (decrease) during the year | C31: 2018 | D31: {=_xlfn.XLOOKUP(B31 &C31,Table3[Metric] &Table3[Year],Table3[Amount],,0)} -> 2945

Sheet Dashboard
A1: COCA-COLA Company Performance DASHBOARD (2009-2018)
